Workbook

Sheet Instructions
A1: AI Maturity Assessment — v1
A3: How to use this assessment
A5: 1. Fill in the Respondent Info tab with your name, role, organization, and date.
A6: 2. Open the Survey tab. For each question, select the response that best describes your organization from the dropdown in the Response column.
A7: 3. Use the Evidence / Notes column (column P) to capture supporting documentation, examples, or context.
A8: 4. Leave a row blank if you are not ready to answer — the assessment will exclude it from scoring automatically.
A9: 5. The Dashboard, Gap Analysis, and Recommendations Output tabs update automatically as you select responses.
A11: About the response options
A12: • Each question offers 5 maturity-coded statements. Select the one that most accurately reflects your organization today — not your aspiration.
A13: • If you are unsure about a question, choose "Not sure" — this flags an awareness gap without affecting your maturity score.
A14: • If a question genuinely does not apply to your organization, choose "Not applicable" — same treatment, different flag.

Sheet Respondent Info
A1: AI Maturity Assessment — Respondent Information
A3: Respondent Name
A4: Role / Title
A5: Function / Department
A6: Date Completed
A7: Organization
A8: Engagement / Project Reference
A9: Notes

Sheet Survey
A1: Question ID | B1: Domain | C1: Subsection | D1: Capability | E1: Question Type | F1: Primary Audience | G1: Secondary Audience | H1: Response Type | I1: Question | J1: Response | K1: Hidden Score | L1: Score Treatment | M1: Gap Flag | N1: Recommendation ID | O1: Evidence Required | P1: Evidence / Notes | Q1: NIST AI RMF Mapping | R1: ISO 42001 Mapping
A2: GOV-001 | B2: AI Council Governance and Framework Charter | C2: The AI Council (Structure & Authority) | D2: AI Executive Accountability | E2: Capability | F2: Executive | G2: Governance/Risk/Compliance | H2: Single-select dropdown | I2: Which best describes executive accountability for AI in your organization? | J2: A named executive owns enterprise AI strategy, governance, funding, and prioritization | K2: =IFERROR(_xlfn.XLOOKUP($A2&"|"&$J2,'Response Mapping'!$C$2:$C$1086,'Response Mapping'!$D$2:$D$1086),"") -> 4 | L2: =IFERROR(_xlfn.XLOOKUP($A2&"|"&$J2,'Response Mapping'!$C$2:$C$1086,'Response Mapping'!$E$2:$E$1086),"") -> Include | M2: =IFERROR(_xlfn.XLOOKUP($A2&"|"&$J2,'Response Mapping'!$C$2:$C$1086,'Response Mapping'!$F$2:$F$1086),"") -> Mature Capability | N2: =IFERROR(_xlfn.XLOOKUP($A2&"|"&$J2,'Response Mapping'!$C$2:$C$1086,'Response Mapping'!$G$2:$G$1086),"") -> REC-GOV-001-L4 | O2: =IF($K2="","",IF($K2>=4,"Yes","No")) -> Yes | Q2: Govern | R2: Clause 5 (Leadership)
A3: GOV-002 | B3: AI Council Governance and Framework Charter | C3: The AI Council (Structure & Authority) | D3: Cross-Functional AI Governance | E3: Capability | F3: Governance/Risk/Compliance | G3: Executive | H3: Single-select dropdown | I3: Which best describes the cross-functional representation of your AI governance council or equivalent decision-making body? | J3: The governance body includes consistent representation from IT, business units, legal, security/risk, HR, and data/analytics, with defined roles and decision rights | K3: =IFERROR(_xlfn.XLOOKUP($A3&"|"&$J3,'Response Mapping'!$C$2:$C$1086,'Response Mapping'!$D$2:$D$1086),"") -> 4 | L3: =IFERROR(_xlfn.XLOOKUP($A3&"|"&$J3,'Response Mapping'!$C$2:$C$1086,'Response Mapping'!$E$2:$E$1086),"") -> Include | M3: =IFERROR(_xlfn.XLOOKUP($A3&"|"&$J3,'Response Mapping'!$C$2:$C$1086,'Response Mapping'!$F$2:$F$1086),"") -> Mature Capability | N3: =IFERROR(_xlfn.XLOOKUP($A3&"|"&$J3,'Response Mapping'!$C$2:$C$1086,'Response Mapping'!$G$2:$G$1086),"") -> REC-GOV-002-L4 | O3: =IF($K3="","",IF($K3>=4,"Yes","No")) -> Yes | Q3: Govern | R3: Clause 5 (Leadership)
A4: GOV-003 | B4: AI Council Governance and Framework Charter | C4: The AI Council (Structure & Authority) | D4: Governance Authority and Decision Rights | E4: Capability | F4: Governance/Risk/Compliance | G4: Executive | H4: Single-select dropdown | I4: Which best describes the authority of your AI governance council to approve, pause, or stop AI initiatives based on risk? | J4: The council can review AI initiatives, but its authority to enforce decisions is unclear or inconsistently applied | K4: =IFERROR(_xlfn.XLOOKUP($A4&"|"&$J4,'Response Mapping'!$C$2:$C$1086,'Response Mapping'!$D$2:$D$1086),"") -> 3 | L4: =IFERROR(_xlfn.XLOOKUP($A4&"|"&$J4,'Response Mapping'!$C$2:$C$1086,'Response Mapping'!$E$2:$E$1086),"") -> Include | M4: =IFERROR(_xlfn.XLOOKUP($A4&"|"&$J4,'Response Mapping'!$C$2:$C$1086,'Response Mapping'!$F$2:$F$1086),"") -> Partial Capability | N4: =IFERROR(_xlfn.XLOOKUP($A4&"|"&$J4,'Response Mapping'!$C$2:$C$1086,'Response Mapping'!$G$2:$G$1086),"") -> REC-GOV-003-L3 | O4: =IF($K4="","",IF($K4>=4,"Yes","No")) -> No | Q4: Govern | R4: Clause 6 (Planning)
A5: GOV-004 | B5: AI Council Governance and Framework Charter | C5: The AI Council (Structure & Authority) | D5: Governance Cadence and Responsiveness | E5: Capability | F5: Governance/Risk/Compliance | G5: Executive | H5: Single-select dropdown | I5: Which best describes the meeting cadence and responsiveness of your AI governance council or review process? | J5: The council meets periodically, but the cadence is not always sufficient to support timely AI review and approval | K5: =IFERROR(_xlfn.XLOOKUP($A5&"|"&$J5,'Response Mapping'!$C$2:$C$1086,'Response Mapping'!$D$2:$D$1086),"") -> 3 | L5: =IFERROR(_xlfn.XLOOKUP($A5&"|"&$J5,'Response Mapping'!$C$2:$C$1086,'Response Mapping'!$E$2:$E$1086),"") -> Include | M5: =IFERROR(_xlfn.XLOOKUP($A5&"|"&$J5,'Response Mapping'!$C$2:$C$1086,'Response Mapping'!$F$2:$F$1086),"") -> Partial Capability | N5: =IFERROR(_xlfn.XLOOKUP($A5&"|"&$J5,'Response Mapping'!$C$2:$C$1086,'Response Mapping'!$G$2:$G$1086),"") -> REC-GOV-004-L3 | O5: =IF($K5="","",IF($K5>=4,"Yes","No")) -> No | Q5: Govern | R5: Clause 9 (Performance Evaluation)
A6: GOV-005 | B6: AI Council Governance and Framework Charter | C6: The AI Council (Structure & Authority) | D6: AI Risk Escalation and Tie-Breaking | E6: Capability | F6: Governance/Risk/Compliance | G6: Executive | H6: Single-select dropdown | I6: Which best describes how AI risk disagreements are escalated and resolved? | J6: Disagreements are handled informally between teams, with no documented tie-breaking authority | K6: =IFERROR(_xlfn.XLOOKUP($A6&"|"&$J6,'Response Mapping'!$C$2:$C$1086,'Response Mapping'!$D$2:$D$1086),"") -> 2 | L6: =IFERROR(_xlfn.XLOOKUP($A6&"|"&$J6,'Response Mapping'!$C$2:$C$1086,'Response Mapping'!$E$2:$E$1086),"") -> Include | M6: =IFERROR(_xlfn.XLOOKUP($A6&"|"&$J6,'Response Mapping'!$C$2:$C$1086,'Response Mapping'!$F$2:$F$1086),"") -> Informal Governance | N6: =IFERROR(_xlfn.XLOOKUP($A6&"|"&$J6,'Response Mapping'!$C$2:$C$1086,'Response Mapping'!$G$2:$G$1086),"") -> REC-GOV-005-L1 | O6: =IF($K6="","",IF($K6>=4,"Yes","No")) -> No | Q6: Govern | R6: Clause 6 (Planning)
A7: GOV-006 | B7: AI Council Governance and Framework Charter | C7: Governance Framework (Policies & Standards) | D7: AI Risk Classification | E7: Capability | F7: Governance/Risk/Compliance | G7: IT/Architecture | H7: Single-select dropdown | I7: Which best describes your organization's process for classifying AI use cases by risk level? | J7: AI use cases are classified into defined risk tiers, and each tier triggers specific review, approval, documentation, and oversight requirements | K7: =IFERROR(_xlfn.XLOOKUP($A7&"|"&$J7,'Response Mapping'!$C$2:$C$1086,'Response Mapping'!$D$2:$D$1086),"") -> 4 | L7: =IFERROR(_xlfn.XLOOKUP($A7&"|"&$J7,'Response Mapping'!$C$2:$C$1086,'Response Mapping'!$E$2:$E$1086),"") -> Include | M7: =IFERROR(_xlfn.XLOOKUP($A7&"|"&$J7,'Response Mapping'!$C$2:$C$1086,'Response Mapping'!$F$2:$F$1086),"") -> Mature Capability | N7: =IFERROR(_xlfn.XLOOKUP($A7&"|"&$J7,'Response Mapping'!$C$2:$C$1086,'Response Mapping'!$G$2:$G$1086),"") -> REC-GOV-006-L4 | O7: =IF($K7="","",IF($K7>=4,"Yes","No")) -> Yes | Q7: Map | R7: Clause 6.1 (Risk Management)
A8: GOV-007 | B8: AI Council Governance and Framework Charter | C8: Governance Framework (Policies & Standards) | D8: Responsible AI Standards and Metrics | E8: Capability | F8: Governance/Risk/Compliance | G8: Data/Analytics | H8: Single-select dropdown | I8: Which best describes how your organization defines and measures Responsible AI principles such as fairness, transparency, explainability, privacy, and safety? | J8: Responsible AI principles are discussed in general terms, but are not documented or measured | K8: =IFERROR(_xlfn.XLOOKUP($A8&"|"&$J8,'Response Mapping'!$C$2:$C$1086,'Response Mapping'!$D$2:$D$1086),"") -> 2 | L8: =IFERROR(_xlfn.XLOOKUP($A8&"|"&$J8,'Response Mapping'!$C$2:$C$1086,'Response Mapping'!$E$2:$E$1086),"") -> Include | M8: =IFERROR(_xlfn.XLOOKUP($A8&"|"&$J8,'Response Mapping'!$C$2:$C$1086,'Response Mapping'!$F$2:$F$1086),"") -> Principles Without Controls | N8: =IFERROR(_xlfn.XLOOKUP($A8&"|"&$J8,'Response Mapping'!$C$2:$C$1086,'Response Mapping'!$G$2:$G$1086),"") -> REC-GOV-007-L1 | O8: =IF($K8="","",IF($K8>=4,"Yes","No")) -> No | Q8: Measure | R8: Clause 8 (Operation)
A9: GOV-008 | B9: AI Council Governance and Framework Charter | C9: Governance Framework (Policies & Standards) | D9: Shadow AI Management | E9: Capability | F9: Governance/Risk/Compliance | G9: IT/Architecture | H9: Single-select dropdown | I9: Which best describes your organization's policy and controls for employee use of public or unapproved AI tools? | J9: Shadow AI is actively managed through policy, training, approved enterprise tools, monitoring, exception handling, and periodic compliance review | K9: =IFERROR(_xlfn.XLOOKUP($A9&"|"&$J9,'Response Mapping'!$C$2:$C$1086,'Response Mapping'!$D$2:$D$1086),"") -> 5 | L9: =IFERROR(_xlfn.XLOOKUP($A9&"|"&$J9,'Response Mapping'!$C$2:$C$1086,'Response Mapping'!$E$2:$E$1086),"") -> Include | M9: =IFERROR(_xlfn.XLOOKUP($A9&"|"&$J9,'Response Mapping'!$C$2:$C$1086,'Response Mapping'!$F$2:$F$1086),"") -> Optimized Capability | N9: =IFERROR(_xlfn.XLOOKUP($A9&"|"&$J9,'Response Mapping'!$C$2:$C$1086,'Response Mapping'!$G$2:$G$1086),"") -> REC-GOV-008-L5 | O9: =IF($K9="","",IF($K9>=4,"Yes","No")) -> Yes | Q9: Manage | R9: Clause 8.3 (Operational Controls)
A10: GOV-009 | B10: AI Council Governance and Framework Charter | C10: Governance Framework (Policies & Standards) | D10: AI Documentation and Deployment Readiness | E10: Capability | F10: Engineering/Delivery | G10: Governance/Risk/Compliance | H10: Single-select dropdown | I10: Which best describes the documentation required before an AI solution is approved for deployment? | J10: Documentation is created inconsistently and varies by team or project | K10: =IFERROR(_xlfn.XLOOKUP($A10&"|"&$J10,'Response Mapping'!$C$2:$C$1086,'Response Mapping'!$D$2:$D$1086),"") -> 2 | L10: =IFERROR(_xlfn.XLOOKUP($A10&"|"&$J10,'Response Mapping'!$C$2:$C$1086,'Response Mapping'!$E$2:$E$1086),"") -> Include | M10: =IFERROR(_xlfn.XLOOKUP($A10&"|"&$J10,'Response Mapping'!$C$2:$C$1086,'Response Mapping'!$F$2:$F$1086),"") -> Inconsistent Practice | N10: =IFERROR(_xlfn.XLOOKUP($A10&"|"&$J10,'Response Mapping'!$C$2:$C$1086,'Response Mapping'!$G$2:$G$1086),"") -> REC-GOV-009-L1 | O10: =IF($K10="","",IF($K10>=4,"Yes","No")) -> No | Q10: Govern | R10: Clause 7.5 (Documented Information)
A11: GOV-010 | B11: AI Council Governance and Framework Charter | C11: Governance Framework (Policies & Standards) | D11: Regulatory and Standards Alignment | E11: Capability | F11: Governance/Risk/Compliance | G11: Executive | H11: Single-select dropdown | I11: Which best describes how your AI governance framework aligns to current and emerging AI regulations, standards, and risk management frameworks? | J11: Some AI policies or controls reference external frameworks, but coverage is incomplete or inconsistently maintained | K11: =IFERROR(_xlfn.XLOOKUP($A11&"|"&$J11,'Response Mapping'!$C$2:$C$1086,'Response Mapping'!$D$2:$D$1086),"") -> 3 | L11: =IFERROR(_xlfn.XLOOKUP($A11&"|"&$J11,'Response Mapping'!$C$2:$C$1086,'Response Mapping'!$E$2:$E$1086),"") -> Include | M11: =IFERROR(_xlfn.XLOOKUP($A11&"|"&$J11,'Response Mapping'!$C$2:$C$1086,'Response Mapping'!$F$2:$F$1086),"") -> Partial Capability | N11: =IFERROR(_xlfn.XLOOKUP($A11&"|"&$J11,'Response Mapping'!$C$2:$C$1086,'Response Mapping'!$G$2:$G$1086),"") -> REC-GOV-010-L3 | O11: =IF($K11="","",IF($K11>=4,"Yes","No")) -> No | Q11: Govern | R11: Clause 4 (Context of the Organization)
A12: GOV-011 | B12: AI Council Governance and Framework Charter | C12: Operational Gaps (Implementation) | D12: AI Asset Inventory | E12: Capability | F12: Governance/Risk/Compliance | G12: IT/Architecture | H12: Single-select dropdown | I12: Which best describes your organization's ability to inventory and track all AI models and AI-enabled vendor capabilities in use? | J12: A central inventory exists, but it is incomplete, manually maintained, or omits embedded vendor AI capabilities | K12: =IFERROR(_xlfn.XLOOKUP($A12&"|"&$J12,'Response Mapping'!$C$2:$C$1086,'Response Mapping'!$D$2:$D$1086),"") -> 3 | L12: =IFERROR(_xlfn.XLOOKUP($A12&"|"&$J12,'Response Mapping'!$C$2:$C$1086,'Response Mapping'!$E$2:$E$1086),"") -> Include | M12: =IFERROR(_xlfn.XLOOKUP($A12&"|"&$J12,'Response Mapping'!$C$2:$C$1086,'Response Mapping'!$F$2:$F$1086),"") -> Partial Capability | N12: =IFERROR(_xlfn.XLOOKUP($A12&"|"&$J12,'Response Mapping'!$C$2:$C$1086,'Response Mapping'!$G$2:$G$1086),"") -> REC-GOV-011-L3 | O12: =IF($K12="","",IF($K12>=4,"Yes","No")) -> No | Q12: Map | R12: Clause 7.5 (Documented Information)
A13: GOV-012 | B13: AI Council Governance and Framework Charter | C13: Operational Gaps (Implementation) | D13: Third-Party AI Risk | E13: Capability | F13: Governance/Risk/Compliance | G13: IT/Architecture | H13: Single-select dropdown | I13: Which best describes your organization's approach to assessing and managing risk for vendor-supplied AI tools and AI-enabled products? | J13: An AI vendor review exists, but coverage of transparency, training data, audit rights, and model updates is inconsistent | K13: =IFERROR(_xlfn.XLOOKUP($A13&"|"&$J13,'Response Mapping'!$C$2:$C$1086,'Response Mapping'!$D$2:$D$1086),"") -> 3 | L13: =IFERROR(_xlfn.XLOOKUP($A13&"|"&$J13,'Response Mapping'!$C$2:$C$1086,'Response Mapping'!$E$2:$E$1086),"") -> Include | M13: =IFERROR(_xlfn.XLOOKUP($A13&"|"&$J13,'Response Mapping'!$C$2:$C$1086,'Response Mapping'!$F$2:$F$1086),"") -> Partial Capability | N13: =IFERROR(_xlfn.XLOOKUP($A13&"|"&$J13,'Response Mapping'!$C$2:$C$1086,'Response Mapping'!$G$2:$G$1086),"") -> REC-GOV-012-L3 | O13: =IF($K13="","",IF($K13>=4,"Yes","No")) -> No | Q13: Manage | R13: Clause 8.4 (Supplier and Third-Party Controls)
... A156: RAC-015 | B156: RACI Matrix | C156: Communication & Awareness (The "Informed") | D156: Vendor Model Change Awareness | E156: Capability | F156: IT/Architecture | G156: Governance/Risk/Compliance | H156: Single-select dropdown | I156: Which best describes who is informed and responsible when an underlying AI vendor releases an API or model change? | J156: Vendor change awareness is automated, integrated with regression testing, supports rapid response to breaking changes, and feeds vendor risk management | K156: =IFERROR(_xlfn.XLOOKUP($A156&"|"&$J156,'Response Mapping'!$C$2:$C$1086,'Response Mapping'!$D$2:$D$1086),"") -> 5 | L156: =IFERROR(_xlfn.XLOOKUP($A156&"|"&$J156,'Response Mapping'!$C$2:$C$1086,'Response Mapping'!$E$2:$E$1086),"") -> Include | M156: =IFERROR(_xlfn.XLOOKUP($A156&"|"&$J156,'Response Mapping'!$C$2:$C$1086,'Response Mapping'!$F$2:$F$1086),"") -> Optimized Capability | N156: =IFERROR(_xlfn.XLOOKUP($A156&"|"&$J156,'Response Mapping'!$C$2:$C$1086,'Response Mapping'!$G$2:$G$1086),"") -> REC-RAC-015-L5 | O156: =IF($K156="","",IF($K156>=4,"Yes","No")) -> Yes | Q156: Manage | R156: Clause 8.4 (Supplier and Third-Party Controls)

Sheet Response Mapping
A1: Question ID | B1: Response Option | C1: Lookup Key | D1: Normalized Score | E1: Score Treatment | F1: Gap Flag | G1: Recommendation ID | H1: Evidence Trigger | I1: Dashboard Category
A2: GOV-001 | B2: No clear executive owner exists for AI | C2: GOV-001|No clear executive owner exists for AI | D2: 1 | E2: Include | F2: Governance Gap | G2: REC-GOV-001-L1 | H2: No | I2: AI Council Governance and Framework Charter
A3: GOV-001 | B3: AI accountability is informal or distributed across multiple leaders without a clear decision owner | C3: GOV-001|AI accountability is informal or distributed across multiple leaders without a clear decision owner | D3: 2 | E3: Include | F3: Governance Gap | G3: REC-GOV-001-L1 | H3: No | I3: AI Council Governance and Framework Charter
A4: GOV-001 | B4: A senior leader or function owns AI strategy, but authority, funding, or decision rights are limited | C4: GOV-001|A senior leader or function owns AI strategy, but authority, funding, or decision rights are limited | D4: 3 | E4: Include | F4: Partial Capability | G4: REC-GOV-001-L3 | H4: No | I4: AI Council Governance and Framework Charter
A5: GOV-001 | B5: A named executive owns enterprise AI strategy, governance, funding, and prioritization | C5: GOV-001|A named executive owns enterprise AI strategy, governance, funding, and prioritization | D5: 4 | E5: Include | F5: Mature Capability | G5: REC-GOV-001-L4 | H5: Yes | I5: AI Council Governance and Framework Charter
A6: GOV-001 | B6: A named executive owns AI accountability and is supported by formal governance, KPIs, risk oversight, and enterprise-wide operating model integration | C6: GOV-001|A named executive owns AI accountability and is supported by formal governance, KPIs, risk oversight, and enterprise-wide operating model integration | D6: 5 | E6: Include | F6: Optimized Capability | G6: REC-GOV-001-L5 | H6: Yes | I6: AI Council Governance and Framework Charter
A7: GOV-001 | B7: Not sure | C7: GOV-001|Not sure | E7: Exclude | F7: Awareness Gap | G7: REC-GOV-001-NS | H7: No | I7: AI Council Governance and Framework Charter
A8: GOV-001 | B8: Not applicable | C8: GOV-001|Not applicable | E8: Exclude | F8: Review Required | G8: REC-GOV-001-NA | H8: No | I8: AI Council Governance and Framework Charter
A9: GOV-002 | B9: No AI governance council or equivalent decision-making body exists | C9: GOV-002|No AI governance council or equivalent decision-making body exists | D9: 1 | E9: Include | F9: Governance Gap | G9: REC-GOV-002-L1 | H9: No | I9: AI Council Governance and Framework Charter
A10: GOV-002 | B10: AI governance is primarily IT-led, with limited business, legal, HR, risk, or ethics involvement | C10: GOV-002|AI governance is primarily IT-led, with limited business, legal, HR, risk, or ethics involvement | D10: 2 | E10: Include | F10: Cross-Functional Gap | G10: REC-GOV-002-L1 | H10: No | I10: AI Council Governance and Framework Charter
A11: GOV-002 | B11: The governance body includes some non-technical representation, but participation is inconsistent or decision rights are unclear | C11: GOV-002|The governance body includes some non-technical representation, but participation is inconsistent or decision rights are unclear | D11: 3 | E11: Include | F11: Partial Capability | G11: REC-GOV-002-L3 | H11: No | I11: AI Council Governance and Framework Charter
A12: GOV-002 | B12: The governance body includes consistent representation from IT, business units, legal, security/risk, HR, and data/analytics, with defined roles and decision rights | C12: GOV-002|The governance body includes consistent representation from IT, business units, legal, security/risk, HR, and data/analytics, with defined roles and decision rights | D12: 4 | E12: Include | F12: Mature Capability | G12: REC-GOV-002-L4 | H12: Yes | I12: AI Council Governance and Framework Charter
A13: GOV-002 | B13: The governance body is fully cross-functional, has formal authority, includes technical and non-technical stakeholders, and regularly adjusts membership based on AI portfolio needs | C13: GOV-002|The governance body is fully cross-functional, has formal authority, includes technical and non-technical stakeholders, and regularly adjusts membership based on AI portfolio needs | D13: 5 | E13: Include | F13: Optimized Capability | G13: REC-GOV-002-L5 | H13: Yes | I13: AI Council Governance and Framework Charter
A14: GOV-002 | B14: Not sure | C14: GOV-002|Not sure | E14: Exclude | F14: Awareness Gap | G14: REC-GOV-002-NS | H14: No | I14: AI Council Governance and Framework Charter
A15: GOV-002 | B15: Not applicable | C15: GOV-002|Not applicable | E15: Exclude | F15: Review Required | G15: REC-GOV-002-NA | H15: No | I15: AI Council Governance and Framework Charter
A16: GOV-003 | B16: No formal AI governance authority exists to review or stop AI initiatives | C16: GOV-003|No formal AI governance authority exists to review or stop AI initiatives | D16: 1 | E16: Include | F16: Governance Authority Gap | G16: REC-GOV-003-L1 | H16: No | I16: AI Council Governance and Framework Charter
A17: GOV-003 | B17: The council or review group may provide informal guidance, but cannot formally approve, pause, or stop projects | C17: GOV-003|The council or review group may provide informal guidance, but cannot formally approve, pause, or stop projects | D17: 2 | E17: Include | F17: Advisory-Only Governance | G17: REC-GOV-003-L1 | H17: No | I17: AI Council Governance and Framework Charter
A18: GOV-003 | B18: The council can review AI initiatives, but its authority to enforce decisions is unclear or inconsistently applied | C18: GOV-003|The council can review AI initiatives, but its authority to enforce decisions is unclear or inconsistently applied | D18: 3 | E18: Include | F18: Partial Capability | G18: REC-GOV-003-L3 | H18: No | I18: AI Council Governance and Framework Charter
A19: GOV-003 | B19: The council has documented authority to approve, pause, escalate, or stop AI initiatives based on defined risk criteria | C19: GOV-003|The council has documented authority to approve, pause, escalate, or stop AI initiatives based on defined risk criteria | D19: 4 | E19: Include | F19: Mature Capability | G19: REC-GOV-003-L4 | H19: Yes | I19: AI Council Governance and Framework Charter
A20: GOV-003 | B20: The council has formal decision rights, escalation authority, auditability, and enforcement mechanisms integrated into funding, delivery, and production release processes | C20: GOV-003|The council has formal decision rights, escalation authority, auditability, and enforcement mechanisms integrated into funding, delivery, and production release processes | D20: 5 | E20: Include | F20: Optimized Capability | G20: REC-GOV-003-L5 | H20: Yes | I20: AI Council Governance and Framework Charter
A21: GOV-003 | B21: Not sure | C21: GOV-003|Not sure | E21: Exclude | F21: Awareness Gap | G21: REC-GOV-003-NS | H21: No | I21: AI Council Governance and Framework Charter
A22: GOV-003 | B22: Not applicable | C22: GOV-003|Not applicable | E22: Exclude | F22: Review Required | G22: REC-GOV-003-NA | H22: No | I22: AI Council Governance and Framework Charter
A23: GOV-004 | B23: No recurring AI governance meeting or review cadence exists | C23: GOV-004|No recurring AI governance meeting or review cadence exists | D23: 1 | E23: Include | F23: Governance Gap | G23: REC-GOV-004-L1 | H23: No | I23: AI Council Governance and Framework Charter
A24: GOV-004 | B24: AI governance discussions occur only as needed or after issues arise | C24: GOV-004|AI governance discussions occur only as needed or after issues arise | D24: 2 | E24: Include | F24: Reactive Governance | G24: REC-GOV-004-L1 | H24: No | I24: AI Council Governance and Framework Charter
A25: GOV-004 | B25: The council meets periodically, but the cadence is not always sufficient to support timely AI review and approval | C25: GOV-004|The council meets periodically, but the cadence is not always sufficient to support timely AI review and approval | D25: 3 | E25: Include | F25: Partial Capability | G25: REC-GOV-004-L3 | H25: No | I25: AI Council Governance and Framework Charter
A26: GOV-004 | B26: The council meets on a defined schedule with a clear intake process, agenda, and service-level expectations for reviews | C26: GOV-004|The council meets on a defined schedule with a clear intake process, agenda, and service-level expectations for reviews | D26: 4 | E26: Include | F26: Mature Capability | G26: REC-GOV-004-L4 | H26: Yes | I26: AI Council Governance and Framework Charter
A27: GOV-004 | B27: The council has a structured cadence, rapid review paths for lower-risk use cases, escalation paths for high-risk use cases, and regularly adjusts cadence based on portfolio demand | C27: GOV-004|The council has a structured cadence, rapid review paths for lower-risk use cases, escalation paths for high-risk use cases, and regularly adjusts cadence based on portfolio demand | D27: 5 | E27: Include | F27: Optimized Capability | G27: REC-GOV-004-L5 | H27: Yes | I27: AI Council Governance and Framework Charter
A28: GOV-004 | B28: Not sure | C28: GOV-004|Not sure | E28: Exclude | F28: Awareness Gap | G28: REC-GOV-004-NS | H28: No | I28: AI Council Governance and Framework Charter
A29: GOV-004 | B29: Not applicable | C29: GOV-004|Not applicable | E29: Exclude | F29: Review Required | G29: REC-GOV-004-NA | H29: No | I29: AI Council Governance and Framework Charter
A30: GOV-005 | B30: No defined escalation path exists for AI risk disagreements | C30: GOV-005|No defined escalation path exists for AI risk disagreements | D30: 1 | E30: Include | F30: Escalation Gap | G30: REC-GOV-005-L1 | H30: No | I30: AI Council Governance and Framework Charter
A31: GOV-005 | B31: Disagreements are handled informally between teams, with no documented tie-breaking authority | C31: GOV-005|Disagreements are handled informally between teams, with no documented tie-breaking authority | D31: 2 | E31: Include | F31: Informal Governance | G31: REC-GOV-005-L1 | H31: No | I31: AI Council Governance and Framework Charter
A32: GOV-005 | B32: An escalation path exists in practice, but it is not consistently documented or understood by stakeholders | C32: GOV-005|An escalation path exists in practice, but it is not consistently documented or understood by stakeholders | D32: 3 | E32: Include | F32: Partial Capability | G32: REC-GOV-005-L3 | H32: No | I32: AI Council Governance and Framework Charter
A33: GOV-005 | B33: A documented escalation path defines who makes final decisions when teams disagree on AI risk level or approval status | C33: GOV-005|A documented escalation path defines who makes final decisions when teams disagree on AI risk level or approval status | D33: 4 | E33: Include | F33: Mature Capability | G33: REC-GOV-005-L4 | H33: Yes | I33: AI Council Governance and Framework Charter
A34: GOV-005 | B34: Escalation paths, decision rights, risk ownership, audit trails, and executive tie-breaking authority are formally embedded into the AI governance process | C34: GOV-005|Escalation paths, decision rights, risk ownership, audit trails, and executive tie-breaking authority are formally embedded into the AI governance process | D34: 5 | E34: Include | F34: Optimized Capability | G34: REC-GOV-005-L5 | H34: Yes | I34: AI Council Governance and Framework Charter
A35: GOV-005 | B35: Not sure | C35: GOV-005|Not sure | E35: Exclude | F35: Awareness Gap | G35: REC-GOV-005-NS | H35: No | I35: AI Council Governance and Framework Charter
A36: GOV-005 | B36: Not applicable | C36: GOV-005|Not applicable | E36: Exclude | F36: Review Required | G36: REC-GOV-005-NA | H36: No | I36: AI Council Governance and Framework Charter
A37: GOV-006 | B37: No formal risk tiering system exists for AI use cases | C37: GOV-006|No formal risk tiering system exists for AI use cases | D37: 1 | E37: Include | F37: Risk Management Gap | G37: REC-GOV-006-L1 | H37: No | I37: AI Council Governance and Framework Charter
A38: GOV-006 | B38: AI risk is considered informally, but there is no consistent rubric or classification process | C38: GOV-006|AI risk is considered informally, but there is no consistent rubric or classification process | D38: 2 | E38: Include | F38: Informal Risk Management | G38: REC-GOV-006-L1 | H38: No | I38: AI Council Governance and Framework Charter
A39: GOV-006 | B39: A basic risk classification approach exists, but criteria or oversight requirements are inconsistently applied | C39: GOV-006|A basic risk classification approach exists, but criteria or oversight requirements are inconsistently applied | D39: 3 | E39: Include | F39: Partial Capability | G39: REC-GOV-006-L3 | H39: No | I39: AI Council Governance and Framework Charter
A40: GOV-006 | B40: AI use cases are classified into defined risk tiers, and each tier triggers specific review, approval, documentation, and oversight requirements | C40: GOV-006|AI use cases are classified into defined risk tiers, and each tier triggers specific review, approval, documentation, and oversight requirements | D40: 4 | E40: Include | F40: Mature Capability | G40: REC-GOV-006-L4 | H40: Yes | I40: AI Council Governance and Framework Charter
...

Sheet Recommendations Library
A1: Recommendation ID | B1: Question ID | C1: Trigger Band | D1: Domain | E1: Capability | F1: Recommendation Title | G1: Recommended Action | H1: Priority | I1: Roadmap Horizon
A2: REC-GOV-001-L1 | B2: GOV-001 | C2: L1 | D2: AI Council Governance and Framework Charter | E2: AI Executive Accountability | F2: Establish baseline AI Executive Accountability | G2: AI Executive Accountability is currently absent or ad-hoc. Stand up the foundational practice: assign an owner, document scope and intent, and define a minimum standard the organization will operate against. Use this as the basis for the next maturity step rather than attempting an enterprise-wide rollout. | H2: High | I2: 0-3 months
A3: REC-GOV-001-L3 | B3: GOV-001 | C3: L3 | D3: AI Council Governance and Framework Charter | E3: AI Executive Accountability | F3: Formalize and standardize AI Executive Accountability | G3: AI Executive Accountability exists in partial form. Document standards, decision rights, and review cadence; ensure consistent application across the AI portfolio and close coverage gaps for in-scope use cases or teams. | H3: Medium | I3: 3-6 months
A4: REC-GOV-001-L4 | B4: GOV-001 | C4: L4 | D4: AI Council Governance and Framework Charter | E4: AI Executive Accountability | F4: Integrate AI Executive Accountability into the operating model | G4: AI Executive Accountability is mature. Strengthen by embedding it into delivery, monitoring, and governance processes; tie outcomes to measurable KPIs and assigned owners; align with the AI risk tier and regulatory context. | H4: Medium | I4: 6-12 months
A5: REC-GOV-001-L5 | B5: GOV-001 | C5: L5 | D5: AI Council Governance and Framework Charter | E5: AI Executive Accountability | F5: Sustain and continuously improve AI Executive Accountability | G5: AI Executive Accountability is optimized. Maintain through scheduled review, internal/external benchmarking, and refinement based on incidents, audit findings, and emerging practices. Re-evaluate as the AI portfolio, regulations, and capabilities evolve. | H5: Low | I5: 12+ months
A6: REC-GOV-001-NS | B6: GOV-001 | C6: NS | D6: AI Council Governance and Framework Charter | E6: AI Executive Accountability | F6: Close awareness gap on AI Executive Accountability | G6: The respondent is unsure of the current state. Engage relevant stakeholders (governance, delivery, business sponsors) to confirm, document, and communicate the current state of AI Executive Accountability; treat as an awareness gap to address before scoring this capability. | H6: Medium | I6: 0-3 months
A7: REC-GOV-001-NA | B7: GOV-001 | C7: NA | D7: AI Council Governance and Framework Charter | E7: AI Executive Accountability | F7: Validate applicability of AI Executive Accountability | G7: The respondent indicated AI Executive Accountability is not applicable. Validate with the consultant whether scope, context, or question wording should be adjusted; confirm there are no risk implications of treating this capability as out of scope. | H7: Low | I7: Out of band
A8: REC-GOV-002-L1 | B8: GOV-002 | C8: L1 | D8: AI Council Governance and Framework Charter | E8: Cross-Functional AI Governance | F8: Establish baseline Cross-Functional AI Governance | G8: Cross-Functional AI Governance is currently absent or ad-hoc. Stand up the foundational practice: assign an owner, document scope and intent, and define a minimum standard the organization will operate against. Use this as the basis for the next maturity step rather than attempting an enterprise-wide rollout. | H8: High | I8: 0-3 months
A9: REC-GOV-002-L3 | B9: GOV-002 | C9: L3 | D9: AI Council Governance and Framework Charter | E9: Cross-Functional AI Governance | F9: Formalize and standardize Cross-Functional AI Governance | G9: Cross-Functional AI Governance exists in partial form. Document standards, decision rights, and review cadence; ensure consistent application across the AI portfolio and close coverage gaps for in-scope use cases or teams. | H9: Medium | I9: 3-6 months
A10: REC-GOV-002-L4 | B10: GOV-002 | C10: L4 | D10: AI Council Governance and Framework Charter | E10: Cross-Functional AI Governance | F10: Integrate Cross-Functional AI Governance into the operating model | G10: Cross-Functional AI Governance is mature. Strengthen by embedding it into delivery, monitoring, and governance processes; tie outcomes to measurable KPIs and assigned owners; align with the AI risk tier and regulatory context. | H10: Medium | I10: 6-12 months
A11: REC-GOV-002-L5 | B11: GOV-002 | C11: L5 | D11: AI Council Governance and Framework Charter | E11: Cross-Functional AI Governance | F11: Sustain and continuously improve Cross-Functional AI Governance | G11: Cross-Functional AI Governance is optimized. Maintain through scheduled review, internal/external benchmarking, and refinement based on incidents, audit findings, and emerging practices. Re-evaluate as the AI portfolio, regulations, and capabilities evolve. | H11: Low | I11: 12+ months
A12: REC-GOV-002-NS | B12: GOV-002 | C12: NS | D12: AI Council Governance and Framework Charter | E12: Cross-Functional AI Governance | F12: Close awareness gap on Cross-Functional AI Governance | G12: The respondent is unsure of the current state. Engage relevant stakeholders (governance, delivery, business sponsors) to confirm, document, and communicate the current state of Cross-Functional AI Governance; treat as an awareness gap to address before scoring this capability. | H12: Medium | I12: 0-3 months
... A931: REC-RAC-015-NA | B931: RAC-015 | C931: NA | D931: RACI Matrix | E931: Vendor Model Change Awareness | F931: Validate applicability of Vendor Model Change Awareness | G931: The respondent indicated Vendor Model Change Awareness is not applicable. Validate with the consultant whether scope, context, or question wording should be adjusted; confirm there are no risk implications of treating this capability as out of scope. | H931: Low | I931: Out of band

Sheet Recommendations Output
A1: Question ID | B1: Domain | C1: Capability | D1: Selected Response | E1: Hidden Score | F1: Gap Flag | G1: Recommendation ID | H1: Recommendation Title | I1: Recommended Action | J1: Priority | K1: Roadmap Horizon
A2: =Survey!$A2 -> GOV-001 | B2: =Survey!$B2 -> AI Council Governance and Framework Charter | C2: =Survey!$D2 -> AI Executive Accountability | D2: =Survey!$J2 -> A named executive owns enterprise AI strategy, governance, funding, and prioritization | E2: =Survey!$K2 -> 4 | F2: =Survey!$M2 -> Mature Capability | G2: =Survey!$N2 -> REC-GOV-001-L4 | H2: =IFERROR(_xludf.XLOOKUP(G2,tbl_RecLibrary[Recommendation ID],tbl_RecLibrary[Recommendation Title]),"") | I2: =IFERROR(_xludf.XLOOKUP(G2,tbl_RecLibrary[Recommendation ID],tbl_RecLibrary[Recommended Action]),"") | J2: =IFERROR(_xludf.XLOOKUP(G2,tbl_RecLibrary[Recommendation ID],tbl_RecLibrary[Priority]),"") | K2: =IFERROR(_xludf.XLOOKUP(G2,tbl_RecLibrary[Recommendation ID],tbl_RecLibrary[Roadmap Horizon]),"")
A3: =Survey!$A3 -> GOV-002 | B3: =Survey!$B3 -> AI Council Governance and Framework Charter | C3: =Survey!$D3 -> Cross-Functional AI Governance | D3: =Survey!$J3 -> The governance body includes consistent representation from IT, business units, legal, security/risk, HR, and data/analytics, with defined roles and decision rights | E3: =Survey!$K3 -> 4 | F3: =Survey!$M3 -> Mature Capability | G3: =Survey!$N3 -> REC-GOV-002-L4 | H3: =IFERROR(_xludf.XLOOKUP(G3,tbl_RecLibrary[Recommendation ID],tbl_RecLibrary[Recommendation Title]),"") | I3: =IFERROR(_xludf.XLOOKUP(G3,tbl_RecLibrary[Recommendation ID],tbl_RecLibrary[Recommended Action]),"") | J3: =IFERROR(_xludf.XLOOKUP(G3,tbl_RecLibrary[Recommendation ID],tbl_RecLibrary[Priority]),"") | K3: =IFERROR(_xludf.XLOOKUP(G3,tbl_RecLibrary[Recommendation ID],tbl_RecLibrary[Roadmap Horizon]),"")
A4: =Survey!$A4 -> GOV-003 | B4: =Survey!$B4 -> AI Council Governance and Framework Charter | C4: =Survey!$D4 -> Governance Authority and Decision Rights | D4: =Survey!$J4 -> The council can review AI initiatives, but its authority to enforce decisions is unclear or inconsistently applied | E4: =Survey!$K4 -> 3 | F4: =Survey!$M4 -> Partial Capability | G4: =Survey!$N4 -> REC-GOV-003-L3 | H4: =IFERROR(_xludf.XLOOKUP(G4,tbl_RecLibrary[Recommendation ID],tbl_RecLibrary[Recommendation Title]),"") | I4: =IFERROR(_xludf.XLOOKUP(G4,tbl_RecLibrary[Recommendation ID],tbl_RecLibrary[Recommended Action]),"") | J4: =IFERROR(_xludf.XLOOKUP(G4,tbl_RecLibrary[Recommendation ID],tbl_RecLibrary[Priority]),"") | K4: =IFERROR(_xludf.XLOOKUP(G4,tbl_RecLibrary[Recommendation ID],tbl_RecLibrary[Roadmap Horizon]),"")
A5: =Survey!$A5 -> GOV-004 | B5: =Survey!$B5 -> AI Council Governance and Framework Charter | C5: =Survey!$D5 -> Governance Cadence and Responsiveness | D5: =Survey!$J5 -> The council meets periodically, but the cadence is not always sufficient to support timely AI review and approval | E5: =Survey!$K5 -> 3 | F5: =Survey!$M5 -> Partial Capability | G5: =Survey!$N5 -> REC-GOV-004-L3 | H5: =IFERROR(_xludf.XLOOKUP(G5,tbl_RecLibrary[Recommendation ID],tbl_RecLibrary[Recommendation Title]),"") | I5: =IFERROR(_xludf.XLOOKUP(G5,tbl_RecLibrary[Recommendation ID],tbl_RecLibrary[Recommended Action]),"") | J5: =IFERROR(_xludf.XLOOKUP(G5,tbl_RecLibrary[Recommendation ID],tbl_RecLibrary[Priority]),"") | K5: =IFERROR(_xludf.XLOOKUP(G5,tbl_RecLibrary[Recommendation ID],tbl_RecLibrary[Roadmap Horizon]),"")
A6: =Survey!$A6 -> GOV-005 | B6: =Survey!$B6 -> AI Council Governance and Framework Charter | C6: =Survey!$D6 -> AI Risk Escalation and Tie-Breaking | D6: =Survey!$J6 -> Disagreements are handled informally between teams, with no documented tie-breaking authority | E6: =Survey!$K6 -> 2 | F6: =Survey!$M6 -> Informal Governance | G6: =Survey!$N6 -> REC-GOV-005-L1 | H6: =IFERROR(_xludf.XLOOKUP(G6,tbl_RecLibrary[Recommendation ID],tbl_RecLibrary[Recommendation Title]),"") | I6: =IFERROR(_xludf.XLOOKUP(G6,tbl_RecLibrary[Recommendation ID],tbl_RecLibrary[Recommended Action]),"") | J6: =IFERROR(_xludf.XLOOKUP(G6,tbl_RecLibrary[Recommendation ID],tbl_RecLibrary[Priority]),"") | K6: =IFERROR(_xludf.XLOOKUP(G6,tbl_RecLibrary[Recommendation ID],tbl_RecLibrary[Roadmap Horizon]),"")
A7: =Survey!$A7 -> GOV-006 | B7: =Survey!$B7 -> AI Council Governance and Framework Charter | C7: =Survey!$D7 -> AI Risk Classification | D7: =Survey!$J7 -> AI use cases are classified into defined risk tiers, and each tier triggers specific review, approval, documentation, and oversight requirements | E7: =Survey!$K7 -> 4 | F7: =Survey!$M7 -> Mature Capability | G7: =Survey!$N7 -> REC-GOV-006-L4 | H7: =IFERROR(_xludf.XLOOKUP(G7,tbl_RecLibrary[Recommendation ID],tbl_RecLibrary[Recommendation Title]),"") | I7: =IFERROR(_xludf.XLOOKUP(G7,tbl_RecLibrary[Recommendation ID],tbl_RecLibrary[Recommended Action]),"") | J7: =IFERROR(_xludf.XLOOKUP(G7,tbl_RecLibrary[Recommendation ID],tbl_RecLibrary[Priority]),"") | K7: =IFERROR(_xludf.XLOOKUP(G7,tbl_RecLibrary[Recommendation ID],tbl_RecLibrary[Roadmap Horizon]),"")
A8: =Survey!$A8 -> GOV-007 | B8: =Survey!$B8 -> AI Council Governance and Framework Charter | C8: =Survey!$D8 -> Responsible AI Standards and Metrics | D8: =Survey!$J8 -> Responsible AI principles are discussed in general terms, but are not documented or measured | E8: =Survey!$K8 -> 2 | F8: =Survey!$M8 -> Principles Without Controls | G8: =Survey!$N8 -> REC-GOV-007-L1 | H8: =IFERROR(_xludf.XLOOKUP(G8,tbl_RecLibrary[Recommendation ID],tbl_RecLibrary[Recommendation Title]),"") | I8: =IFERROR(_xludf.XLOOKUP(G8,tbl_RecLibrary[Recommendation ID],tbl_RecLibrary[Recommended Action]),"") | J8: =IFERROR(_xludf.XLOOKUP(G8,tbl_RecLibrary[Recommendation ID],tbl_RecLibrary[Priority]),"") | K8: =IFERROR(_xludf.XLOOKUP(G8,tbl_RecLibrary[Recommendation ID],tbl_RecLibrary[Roadmap Horizon]),"")
A9: =Survey!$A9 -> GOV-008 | B9: =Survey!$B9 -> AI Council Governance and Framework Charter | C9: =Survey!$D9 -> Shadow AI Management | D9: =Survey!$J9 -> Shadow AI is actively managed through policy, training, approved enterprise tools, monitoring, exception handling, and periodic compliance review | E9: =Survey!$K9 -> 5 | F9: =Survey!$M9 -> Optimized Capability | G9: =Survey!$N9 -> REC-GOV-008-L5 | H9: =IFERROR(_xludf.XLOOKUP(G9,tbl_RecLibrary[Recommendation ID],tbl_RecLibrary[Recommendation Title]),"") | I9: =IFERROR(_xludf.XLOOKUP(G9,tbl_RecLibrary[Recommendation ID],tbl_RecLibrary[Recommended Action]),"") | J9: =IFERROR(_xludf.XLOOKUP(G9,tbl_RecLibrary[Recommendation ID],tbl_RecLibrary[Priority]),"") | K9: =IFERROR(_xludf.XLOOKUP(G9,tbl_RecLibrary[Recommendation ID],tbl_RecLibrary[Roadmap Horizon]),"")
A10: =Survey!$A10 -> GOV-009 | B10: =Survey!$B10 -> AI Council Governance and Framework Charter | C10: =Survey!$D10 -> AI Documentation and Deployment Readiness | D10: =Survey!$J10 -> Documentation is created inconsistently and varies by team or project | E10: =Survey!$K10 -> 2 | F10: =Survey!$M10 -> Inconsistent Practice | G10: =Survey!$N10 -> REC-GOV-009-L1 | H10: =IFERROR(_xludf.XLOOKUP(G10,tbl_RecLibrary[Recommendation ID],tbl_RecLibrary[Recommendation Title]),"") | I10: =IFERROR(_xludf.XLOOKUP(G10,tbl_RecLibrary[Recommendation ID],tbl_RecLibrary[Recommended Action]),"") | J10: =IFERROR(_xludf.XLOOKUP(G10,tbl_RecLibrary[Recommendation ID],tbl_RecLibrary[Priority]),"") | K10: =IFERROR(_xludf.XLOOKUP(G10,tbl_RecLibrary[Recommendation ID],tbl_RecLibrary[Roadmap Horizon]),"")
A11: =Survey!$A11 -> GOV-010 | B11: =Survey!$B11 -> AI Council Governance and Framework Charter | C11: =Survey!$D11 -> Regulatory and Standards Alignment | D11: =Survey!$J11 -> Some AI policies or controls reference external frameworks, but coverage is incomplete or inconsistently maintained | E11: =Survey!$K11 -> 3 | F11: =Survey!$M11 -> Partial Capability | G11: =Survey!$N11 -> REC-GOV-010-L3 | H11: =IFERROR(_xludf.XLOOKUP(G11,tbl_RecLibrary[Recommendation ID],tbl_RecLibrary[Recommendation Title]),"") | I11: =IFERROR(_xludf.XLOOKUP(G11,tbl_RecLibrary[Recommendation ID],tbl_RecLibrary[Recommended Action]),"") | J11: =IFERROR(_xludf.XLOOKUP(G11,tbl_RecLibrary[Recommendation ID],tbl_RecLibrary[Priority]),"") | K11: =IFERROR(_xludf.XLOOKUP(G11,tbl_RecLibrary[Recommendation ID],tbl_RecLibrary[Roadmap Horizon]),"")
A12: =Survey!$A12 -> GOV-011 | B12: =Survey!$B12 -> AI Council Governance and Framework Charter | C12: =Survey!$D12 -> AI Asset Inventory | D12: =Survey!$J12 -> A central inventory exists, but it is incomplete, manually maintained, or omits embedded vendor AI capabilities | E12: =Survey!$K12 -> 3 | F12: =Survey!$M12 -> Partial Capability | G12: =Survey!$N12 -> REC-GOV-011-L3 | H12: =IFERROR(_xludf.XLOOKUP(G12,tbl_RecLibrary[Recommendation ID],tbl_RecLibrary[Recommendation Title]),"") | I12: =IFERROR(_xludf.XLOOKUP(G12,tbl_RecLibrary[Recommendation ID],tbl_RecLibrary[Recommended Action]),"") | J12: =IFERROR(_xludf.XLOOKUP(G12,tbl_RecLibrary[Recommendation ID],tbl_RecLibrary[Priority]),"") | K12: =IFERROR(_xludf.XLOOKUP(G12,tbl_RecLibrary[Recommendation ID],tbl_RecLibrary[Roadmap Horizon]),"")
A13: =Survey!$A13 -> GOV-012 | B13: =Survey!$B13 -> AI Council Governance and Framework Charter | C13: =Survey!$D13 -> Third-Party AI Risk | D13: =Survey!$J13 -> An AI vendor review exists, but coverage of transparency, training data, audit rights, and model updates is inconsistent | E13: =Survey!$K13 -> 3 | F13: =Survey!$M13 -> Partial Capability | G13: =Survey!$N13 -> REC-GOV-012-L3 | H13: =IFERROR(_xludf.XLOOKUP(G13,tbl_RecLibrary[Recommendation ID],tbl_RecLibrary[Recommendation Title]),"") | I13: =IFERROR(_xludf.XLOOKUP(G13,tbl_RecLibrary[Recommendation ID],tbl_RecLibrary[Recommended Action]),"") | J13: =IFERROR(_xludf.XLOOKUP(G13,tbl_RecLibrary[Recommendation ID],tbl_RecLibrary[Priority]),"") | K13: =IFERROR(_xludf.XLOOKUP(G13,tbl_RecLibrary[Recommendation ID],tbl_RecLibrary[Roadmap Horizon]),"")
... A19: =Survey!$A19 -> GOV-018 | B19: =Survey!$B19 -> AI Council Governance and Framework Charter | C19: =Survey!$D19 -> Speak-Up Culture for AI Risk | D19: =Survey!$J19 -> A documented, communicated channel allows employees to raise AI concerns, including anonymously, with a defined triage and response process | E19: =Survey!$K19 -> 4 | F19: =Survey!$M19 -> Mature Capability | G19: =Survey!$N19 -> REC-GOV-018-L4 | H19: =IFERROR(_xludf.XLOOKUP(G19,tbl_RecLibrary[Recommendation ID],tbl_RecLibrary[Recommendation Title]),"") | I19: =IFERROR(_xludf.XLOOKUP(G19,tbl_RecLibrary[Recommendation ID],tbl_RecLibrary[Recommended Action]),"") | J19: =IFERROR(_xludf.XLOOKUP(G19,tbl_RecLibrary[Recommendation ID],tbl_RecLibrary[Priority]),"") | K19: =IFERROR(_xludf.XLOOKUP(G19,tbl_RecLibrary[Recommendation ID],tbl_RecLibrary[Roadmap Horizon]),"")
A20: =Survey!$A20 -> STR-001 | B20: =Survey!$B20 -> AI Strategy and Roadmap | C20: =Survey!$D20 -> AI Business Value Articulation | D20: =Survey!#REF! -> #REF! | E20: =Survey!$K20 -> 4 | F20: =Survey!$M20 -> Mature Capability | G20: =Survey!$N20 -> REC-STR-001-L4 | H20: =IFERROR(_xludf.XLOOKUP(G20,tbl_RecLibrary[Recommendation ID],tbl_RecLibrary[Recommendation Title]),"") | I20: =IFERROR(_xludf.XLOOKUP(G20,tbl_RecLibrary[Recommendation ID],tbl_RecLibrary[Recommended Action]),"") | J20: =IFERROR(_xludf.XLOOKUP(G20,tbl_RecLibrary[Recommendation ID],tbl_RecLibrary[Priority]),"") | K20: =IFERROR(_xludf.XLOOKUP(G20,tbl_RecLibrary[Recommendation ID],tbl_RecLibrary[Roadmap Horizon]),"")
A21: =Survey!$A21 -> STR-002 | B21: =Survey!$B21 -> AI Strategy and Roadmap | C21: =Survey!$D21 -> AI Sourcing Strategy | D21: =Survey!$J20 -> Each major AI initiative has a documented business case, named KPI, baseline, target, and accountable owner | E21: =Survey!$K21 -> 4 | F21: =Survey!$M21 -> Mature Capability | G21: =Survey!$N21 -> REC-STR-002-L4 | H21: =IFERROR(_xludf.XLOOKUP(G21,tbl_RecLibrary[Recommendation ID],tbl_RecLibrary[Recommendation Title]),"") | I21: =IFERROR(_xludf.XLOOKUP(G21,tbl_RecLibrary[Recommendation ID],tbl_RecLibrary[Recommended Action]),"") | J21: =IFERROR(_xludf.XLOOKUP(G21,tbl_RecLibrary[Recommendation ID],tbl_RecLibrary[Priority]),"") | K21: =IFERROR(_xludf.XLOOKUP(G21,tbl_RecLibrary[Recommendation ID],tbl_RecLibrary[Roadmap Horizon]),"")
A22: =Survey!$A22 -> STR-003 | B22: =Survey!$B22 -> AI Strategy and Roadmap | C22: =Survey!$D22 -> AI Competitive Strategy | D22: =Survey!$J22 -> Leadership recognizes both parity and differentiation goals, but the portfolio mix is not deliberately managed | E22: =Survey!$K22 -> 3 | F22: =Survey!$M22 -> Partial Capability | G22: =Survey!$N22 -> REC-STR-003-L3 | H22: =IFERROR(_xludf.XLOOKUP(G22,tbl_RecLibrary[Recommendation ID],tbl_RecLibrary[Recommendation Title]),"") | I22: =IFERROR(_xludf.XLOOKUP(G22,tbl_RecLibrary[Recommendation ID],tbl_RecLibrary[Recommended Action]),"") | J22: =IFERROR(_xludf.XLOOKUP(G22,tbl_RecLibrary[Recommendation ID],tbl_RecLibrary[Priority]),"") | K22: =IFERROR(_xludf.XLOOKUP(G22,tbl_RecLibrary[Recommendation ID],tbl_RecLibrary[Roadmap Horizon]),"")
A23: =Survey!$A23 -> STR-004 | B23: =Survey!$B23 -> AI Strategy and Roadmap | C23: =Survey!$D23 -> AI Portfolio Balance | D23: =Survey!$J23 -> One side dominates by default (e.g., all internal productivity, or all customer-facing pilots), with no strategic rationale | E23: =Survey!$K23 -> 2 | F23: =Survey!$M23 -> Imbalanced Portfolio | G23: =Survey!$N23 -> REC-STR-004-L1 | H23: =IFERROR(_xludf.XLOOKUP(G23,tbl_RecLibrary[Recommendation ID],tbl_RecLibrary[Recommendation Title]),"") | I23: =IFERROR(_xludf.XLOOKUP(G23,tbl_RecLibrary[Recommendation ID],tbl_RecLibrary[Recommended Action]),"") | J23: =IFERROR(_xludf.XLOOKUP(G23,tbl_RecLibrary[Recommendation ID],tbl_RecLibrary[Priority]),"") | K23: =IFERROR(_xludf.XLOOKUP(G23,tbl_RecLibrary[Recommendation ID],tbl_RecLibrary[Roadmap Horizon]),"")
A24: =Survey!$A24 -> STR-005 | B24: =Survey!$B24 -> AI Strategy and Roadmap | C24: =Survey!$D24 -> Foundational Data Readiness | D24: =Survey!$J24 -> Data issues are known but not reflected as milestones, dependencies, or funded work in the roadmap | E24: =Survey!$K24 -> 2 | F24: =Survey!$M24 -> Unfunded Data Debt | G24: =Survey!$N24 -> REC-STR-005-L1 | H24: =IFERROR(_xludf.XLOOKUP(G24,tbl_RecLibrary[Recommendation ID],tbl_RecLibrary[Recommendation Title]),"") | I24: =IFERROR(_xludf.XLOOKUP(G24,tbl_RecLibrary[Recommendation ID],tbl_RecLibrary[Recommended Action]),"") | J24: =IFERROR(_xludf.XLOOKUP(G24,tbl_RecLibrary[Recommendation ID],tbl_RecLibrary[Priority]),"") | K24: =IFERROR(_xludf.XLOOKUP(G24,tbl_RecLibrary[Recommendation ID],tbl_RecLibrary[Roadmap Horizon]),"")
A25: =Survey!$A25 -> STR-006 | B25: =Survey!$B25 -> AI Strategy and Roadmap | C25: =Survey!$D25 -> Portfolio Horizon Balance | D25: =Survey!$J25 -> Some short-term and long-term work exists, but the balance is accidental rather than deliberate | E25: =Survey!$K25 -> 2 | F25: =Survey!$M25 -> Unintentional Mix | G25: =Survey!$N25 -> REC-STR-006-L1 | H25: =IFERROR(_xludf.XLOOKUP(G25,tbl_RecLibrary[Recommendation ID],tbl_RecLibrary[Recommendation Title]),"") | I25: =IFERROR(_xludf.XLOOKUP(G25,tbl_RecLibrary[Recommendation ID],tbl_RecLibrary[Recommended Action]),"") | J25: =IFERROR(_xludf.XLOOKUP(G25,tbl_RecLibrary[Recommendation ID],tbl_RecLibrary[Priority]),"") | K25: =IFERROR(_xludf.XLOOKUP(G25,tbl_RecLibrary[Recommendation ID],tbl_RecLibrary[Roadmap Horizon]),"")
A26: =Survey!$A26 -> STR-007 | B26: =Survey!$B26 -> AI Strategy and Roadmap | C26: =Survey!$D26 -> Roadmap Dependency Management | D26: =Survey!$J26 -> Dependencies are known informally by individuals, but not documented or used to sequence work | E26: =Survey!$K26 -> 2 | F26: =Survey!$M26 -> Tribal Knowledge | G26: =Survey!$N26 -> REC-STR-007-L1 | H26: =IFERROR(_xludf.XLOOKUP(G26,tbl_RecLibrary[Recommendation ID],tbl_RecLibrary[Recommendation Title]),"") | I26: =IFERROR(_xludf.XLOOKUP(G26,tbl_RecLibrary[Recommendation ID],tbl_RecLibrary[Recommended Action]),"") | J26: =IFERROR(_xludf.XLOOKUP(G26,tbl_RecLibrary[Recommendation ID],tbl_RecLibrary[Priority]),"") | K26: =IFERROR(_xludf.XLOOKUP(G26,tbl_RecLibrary[Recommendation ID],tbl_RecLibrary[Roadmap Horizon]),"")
A27: =Survey!$A27 -> STR-008 | B27: =Survey!$B27 -> AI Strategy and Roadmap | C27: =Survey!$D27 -> Roadmap Refresh and Project Termination | D27: =Survey!$J27 -> The roadmap is reviewed periodically, but stop/continue decisions are inconsistent or politically difficult | E27: =Survey!$K27 -> 3 | F27: =Survey!$M27 -> Partial Capability | G27: =Survey!$N27 -> REC-STR-008-L3 | H27: =IFERROR(_xludf.XLOOKUP(G27,tbl_RecLibrary[Recommendation ID],tbl_RecLibrary[Recommendation Title]),"") | I27: =IFERROR(_xludf.XLOOKUP(G27,tbl_RecLibrary[Recommendation ID],tbl_RecLibrary[Recommended Action]),"") | J27: =IFERROR(_xludf.XLOOKUP(G27,tbl_RecLibrary[Recommendation ID],tbl_RecLibrary[Priority]),"") | K27: =IFERROR(_xludf.XLOOKUP(G27,tbl_RecLibrary[Recommendation ID],tbl_RecLibrary[Roadmap Horizon]),"")
A28: =Survey!$A28 -> STR-009 | B28: =Survey!$B28 -> AI Strategy and Roadmap | C28: =Survey!$D28 -> AI Talent Strategy | D28: =Survey!$J28 -> Some internal AI capability exists, but key roles (e.g., ML engineering, MLOps, data engineering) are heavily dependent on contractors | E28: =Survey!$K28 -> 2 | F28: =Survey!$M28 -> External Dependency | G28: =Survey!$N28 -> REC-STR-009-L1 | H28: =IFERROR(_xludf.XLOOKUP(G28,tbl_RecLibrary[Recommendation ID],tbl_RecLibrary[Recommendation Title]),"") | I28: =IFERROR(_xludf.XLOOKUP(G28,tbl_RecLibrary[Recommendation ID],tbl_RecLibrary[Recommended Action]),"") | J28: =IFERROR(_xludf.XLOOKUP(G28,tbl_RecLibrary[Recommendation ID],tbl_RecLibrary[Priority]),"") | K28: =IFERROR(_xludf.XLOOKUP(G28,tbl_RecLibrary[Recommendation ID],tbl_RecLibrary[Roadmap Horizon]),"")
A29: =Survey!$A29 -> STR-010 | B29: =Survey!$B29 -> AI Strategy and Roadmap | C29: =Survey!$D29 -> AI Cost Forecasting | D29: =Survey!$J29 -> AI run costs are continuously monitored, attributed to business outcomes, optimized through architecture and model selection, and integrated with FinOps practices | E29: =Survey!$K29 -> 5 | F29: =Survey!$M29 -> Optimized Capability | G29: =Survey!$N29 -> REC-STR-010-L5 | H29: =IFERROR(_xludf.XLOOKUP(G29,tbl_RecLibrary[Recommendation ID],tbl_RecLibrary[Recommendation Title]),"") | I29: =IFERROR(_xludf.XLOOKUP(G29,tbl_RecLibrary[Recommendation ID],tbl_RecLibrary[Recommended Action]),"") | J29: =IFERROR(_xludf.XLOOKUP(G29,tbl_RecLibrary[Recommendation ID],tbl_RecLibrary[Priority]),"") | K29: =IFERROR(_xludf.XLOOKUP(G29,tbl_RecLibrary[Recommendation ID],tbl_RecLibrary[Roadmap Horizon]),"")
A30: =Survey!$A30 -> STR-011 | B30: =Survey!$B30 -> AI Strategy and Roadmap | C30: =Survey!$D30 -> Subject-Matter Expert Engagement | D30: =Survey!$J30 -> Some initiatives have allocated SME time, but the practice is inconsistent across the portfolio | E30: =Survey!$K30 -> 3 | F30: =Survey!$M30 -> Partial Capability | G30: =Survey!$N30 -> REC-STR-011-L3 | H30: =IFERROR(_xludf.XLOOKUP(G30,tbl_RecLibrary[Recommendation ID],tbl_RecLibrary[Recommendation Title]),"") | I30: =IFERROR(_xludf.XLOOKUP(G30,tbl_RecLibrary[Recommendation ID],tbl_RecLibrary[Recommended Action]),"") | J30: =IFERROR(_xludf.XLOOKUP(G30,tbl_RecLibrary[Recommendation ID],tbl_RecLibrary[Priority]),"") | K30: =IFERROR(_xludf.XLOOKUP(G30,tbl_RecLibrary[Recommendation ID],tbl_RecLibrary[Roadmap Horizon]),"")
A31: =Survey!$A31 -> STR-012 | B31: =Survey!$B31 -> AI Strategy and Roadmap | C31: =Survey!$D31 -> End-User AI Enablement | D31: =Survey!$J31 -> A documented workforce AI enablement plan covers role-based training, communications, and adoption measurement for each major AI tool | E31: =Survey!$K31 -> 4 | F31: =Survey!$M31 -> Mature Capability | G31: =Survey!$N31 -> REC-STR-012-L4 | H31: =IFERROR(_xludf.XLOOKUP(G31,tbl_RecLibrary[Recommendation ID],tbl_RecLibrary[Recommendation Title]),"") | I31: =IFERROR(_xludf.XLOOKUP(G31,tbl_RecLibrary[Recommendation ID],tbl_RecLibrary[Recommended Action]),"") | J31: =IFERROR(_xludf.XLOOKUP(G31,tbl_RecLibrary[Recommendation ID],tbl_RecLibrary[Priority]),"") | K31: =IFERROR(_xludf.XLOOKUP(G31,tbl_RecLibrary[Recommendation ID],tbl_RecLibrary[Roadmap Horizon]),"")
A32: =Survey!$A32 -> STR-013 | B32: =Survey!$B32 -> AI Strategy and Roadmap | C32: =Survey!$D32 -> AI Success Definition | D32: =Survey!$J32 -> Multiple success measures exist, but the balance between technical and business measures is inconsistent across initiatives | E32: =Survey!$K32 -> 3 | F32: =Survey!$M32 -> Partial Capability | G32: =Survey!$N32 -> REC-STR-013-L3 | H32: =IFERROR(_xludf.XLOOKUP(G32,tbl_RecLibrary[Recommendation ID],tbl_RecLibrary[Recommendation Title]),"") | I32: =IFERROR(_xludf.XLOOKUP(G32,tbl_RecLibrary[Recommendation ID],tbl_RecLibrary[Recommended Action]),"") | J32: =IFERROR(_xludf.XLOOKUP(G32,tbl_RecLibrary[Recommendation ID],tbl_RecLibrary[Priority]),"") | K32: =IFERROR(_xludf.XLOOKUP(G32,tbl_RecLibrary[Recommendation ID],tbl_RecLibrary[Roadmap Horizon]),"")
A33: =Survey!$A33 -> STR-014 | B33: =Survey!$B33 -> AI Strategy and Roadmap | C33: =Survey!$D33 -> AI Investment Time Horizon | D33: =Survey!$J33 -> AI initiatives have defined time-to-value windows aligned to initiative type (e.g., pilot vs. platform vs. strategic bet) | E33: =Survey!$K33 -> 4 | F33: =Survey!$M33 -> Mature Capability | G33: =Survey!$N33 -> REC-STR-014-L4 | H33: =IFERROR(_xludf.XLOOKUP(G33,tbl_RecLibrary[Recommendation ID],tbl_RecLibrary[Recommendation Title]),"") | I33: =IFERROR(_xludf.XLOOKUP(G33,tbl_RecLibrary[Recommendation ID],tbl_RecLibrary[Recommended Action]),"") | J33: =IFERROR(_xludf.XLOOKUP(G33,tbl_RecLibrary[Recommendation ID],tbl_RecLibrary[Priority]),"") | K33: =IFERROR(_xludf.XLOOKUP(G33,tbl_RecLibrary[Recommendation ID],tbl_RecLibrary[Roadmap Horizon]),"")
... A156: =Survey!$A156 -> RAC-015 | B156: =Survey!$B156 -> RACI Matrix | C156: =Survey!$D156 -> Vendor Model Change Awareness | D156: =Survey!$J156 -> Vendor change awareness is automated, integrated with regression testing, supports rapid response to breaking changes, and feeds vendor risk management | E156: =Survey!$K156 -> 5 | F156: =Survey!$M156 -> Optimized Capability | G156: =Survey!$N156 -> REC-RAC-015-L5 | H156: =IFERROR(_xludf.XLOOKUP(G156,tbl_RecLibrary[Recommendation ID],tbl_RecLibrary[Recommendation Title]),"") | I156: =IFERROR(_xludf.XLOOKUP(G156,tbl_RecLibrary[Recommendation ID],tbl_RecLibrary[Recommended Action]),"") | J156: =IFERROR(_xludf.XLOOKUP(G156,tbl_RecLibrary[Recommendation ID],tbl_RecLibrary[Priority]),"") | K156: =IFERROR(_xludf.XLOOKUP(G156,tbl_RecLibrary[Recommendation ID],tbl_RecLibrary[Roadmap Horizon]),"")

Sheet Dashboard
A1: AI Maturity Assessment — Dashboard
A3: Overall Maturity Score | B3: =IFERROR(ROUND(AVERAGE(#REF!),1),"")
A4: Completion % | B4: =IFERROR(COUNTA(#REF!)/COUNTA(#REF!),0) -> 1
A5: Completed / Total | B5: =COUNTA(#REF!)&" / "&COUNTA(#REF!) -> 1 / 1
A6: Not Sure count | B6: =COUNTIF(#REF!,"Not sure") -> #REF!
A7: Not Applicable count | B7: =COUNTIF(#REF!,"Not applicable") -> #REF!
A9: Domain Maturity Scores
A10: AI Council Governance and Framework Charter | B10: =IFERROR(ROUND(AVERAGEIFS(#REF!,#REF!,A10),1),"")
A11: AI Strategy and Roadmap | B11: =IFERROR(ROUND(AVERAGEIFS(#REF!,#REF!,A11),1),"")
A12: Responsible AI Guidelines | B12: =IFERROR(ROUND(AVERAGEIFS(#REF!,#REF!,A12),1),"")
A13: Performance Measurement Framework | B13: =IFERROR(ROUND(AVERAGEIFS(#REF!,#REF!,A13),1),"")
A14: AI Operating Model Blueprint | B14: =IFERROR(ROUND(AVERAGEIFS(#REF!,#REF!,A14),1),"")
A15: Use Case Prioritization Framework | B15: =IFERROR(ROUND(AVERAGEIFS(#REF!,#REF!,A15),1),"")
A16: Training Program for Council and Business Units | B16: =IFERROR(ROUND(AVERAGEIFS(#REF!,#REF!,A16),1),"")
A17: Change Management and Adoption Plan | B17: =IFERROR(ROUND(AVERAGEIFS(#REF!,#REF!,A17),1),"")
A18: Technology Architecture and Guidance | B18: =IFERROR(ROUND(AVERAGEIFS(#REF!,#REF!,A18),1),"")
A19: RACI Matrix | B19: =IFERROR(ROUND(AVERAGEIFS(#REF!,#REF!,A19),1),"")
A40: Recommendations Triggered — High Priority (score 1-2) | B40: =COUNTIFS(#REF!,"<>",#REF!,"<=2") -> #REF!
A41: Recommendations Triggered — Medium Priority (score 3) | B41: =COUNTIFS(#REF!,"<>",#REF!,3) -> #REF!
A42: Recommendations Triggered — Low Priority (score 4-5) | B42: =COUNTIFS(#REF!,"<>",#REF!,">=4") -> #REF!
A43: Recommendations Triggered — Not Sure / Not Applicable | B43: =COUNTIFS(#REF!,"<>",#REF!,"") -> #REF!

Sheet Gap Analysis
A1: Gap Flag | B1: Count in Survey Responses
A2: Governance Gap | B2: =COUNTIF(#REF!,"Governance Gap") -> #REF!
A3: Partial Capability | B3: =COUNTIF(#REF!,"Partial Capability") -> #REF!
A4: Mature Capability | B4: =COUNTIF(#REF!,"Mature Capability") -> #REF!
A5: Optimized Capability | B5: =COUNTIF(#REF!,"Optimized Capability") -> #REF!
A6: Awareness Gap | B6: =COUNTIF(#REF!,"Awareness Gap") -> #REF!
